Workbook

Sheet Dashboard
B1: LIVE PORTFOLIO DASHBOARD · ₹1 Crore, 3-Year Plan
B2: Pick an investor, then type any override in the yellow column. Every number, table and chart on this page recalculates instantly.
B4: SELECT INVESTOR ▸ | C4: Vikram | D4: =INDEX('Investor Personas'!$B$3:$B$6,Dash_Calc!$B$1)&" · "&INDEX('Investor Personas'!$E$3:$E$6,Dash_Calc!$B$1)&" risk" -> The Momentum Maverick · Very High risk | H4: PROJECTED VALUE | J4: EXPECTED CAGR | L4: REQUIRED CAGR | N4: PROBABILITY OF TARGET | P4: PORTFOLIO BETA | R4: VOLATILITY (5Y)
H5: =Dash_Calc!B30 -> 14451037 | J5: =Dash_Calc!B31 -> 0.13057575 | L5: =Dash_Calc!B32 -> 0.29066288 | N5: =Dash_Calc!B37 -> 0.078015433 | P5: =Dash_Calc!B34 -> 0.9695613 | R5: =Dash_Calc!B35 -> 0.16169608
B6: INVESTOR POLICY | C6: Preset | D6: Your override | E6: In use
B7: Corpus (₹) | C7: ='Investor Personas'!$C$1 -> 10000000 | E7: =IF(D7="",C7,D7) -> 10000000 | H7: ="vs target "&TEXT($E$8,"₹#,##0") -> vs target ₹21,500,000 | J7: ="model central estimate" -> model central estimate | L7: ="to hit the target" -> to hit the target | N7: ="lognormal, 5Y volatility" -> lognormal, 5Y volatility | P7: ="1.00 = moves with NIFTY" -> 1.00 = moves with NIFTY | R7: ="annualised, monthly data" -> annualised, monthly data
B8: Target corpus (₹) | C8: =INDEX('Investor Personas'!$C$3:$C$6,Dash_Calc!$B$1) -> 21500000 | E8: =IF(D8="",C8,D8) -> 21500000
B9: Horizon (years) | C9: ='Investor Personas'!$F$1 -> 3 | E9: =IF(D9="",C9,D9) -> 3 | H9: SURPLUS / (SHORTFALL) | J9: EXPECTED SHARPE | L9: STOCKS HELD | N9: LARGEST POSITION | P9: BACKTEST CAGR (5Y) | R9: MAX DRAWDOWN (5Y)
B10: Equity allocation | C10: =INDEX('Investor Personas'!$F$3:$F$6,Dash_Calc!$B$1) -> 0.95 | E10: =IF(D10="",C10,D10) -> 0.95 | H10: =Dash_Calc!B33 -> -7048963.3 | J10: =Dash_Calc!B36 -> 0.35298169 | L10: =Dash_Calc!B38 -> 12 | N10: =Dash_Calc!E28 -> 0.14383291 | P10: =Dash_Calc!E30 -> 0.10828102 | R10: =Dash_Calc!E31 -> -0.21017469
B11: Large-cap share of equity | C11: =INDEX(Dash_Calc!$B$41:$E$41,Dash_Calc!$B$1) -> 0.4 | E11: =IF(D11="",C11,D11) -> 0.4
B12: Mid-cap share of equity | C12: =INDEX(Dash_Calc!$B$42:$E$42,Dash_Calc!$B$1) -> 0.35 | E12: =IF(D12="",C12,D12) -> 0.35 | H12: =IF(Dash_Calc!B33>=0,"on track","gap to close") -> gap to close | J12: ="(Exp. CAGR − Rƒ) ÷ vol" -> (Exp. CAGR − Rƒ) ÷ vol | L12: ="of 14 in the universe" -> of 14 in the universe | N12: =Dash_Calc!E29 -> KEI | P12: ="NIFTY: "&TEXT(Dash_Calc!E32,"0.0%") -> NIFTY: 5.1% | R12: ="today's weights, hypothetical" -> today's weights, hypothetical
B13: Small-cap share of equity | C13: =INDEX(Dash_Calc!$B$43:$E$43,Dash_Calc!$B$1) -> 0.25 | E13: =IF(D13="",C13,D13) -> 0.25
B14: Max beta allowed per stock | C14: =INDEX('Investor Personas'!$I$3:$I$6,Dash_Calc!$B$1) -> 2.5 | E14: =IF(D14="",C14,D14) -> 2.5 | H14: =IF(Dash_Calc!B33>=0,"✔ ON TRACK — the model's expected path reaches the target.",IF(Dash_Calc!B37>=0.3,"◐ STRETCH — target is reachable only with above-model returns ("&TEXT(Dash_Calc!B37,"0%")&" probability).","✖ SHORTFALL — expected "&TEXT(Dash_Calc!B30,"₹#,##0")&" vs target "&TEXT($E$8,"₹#,##0")&". Raise equity / risk, lower the target, or extend the horizon.")) -> ✖ SHORTFALL — expected ₹14,451,037 vs target ₹21,500,000. Raise equity / risk, lower the target, or extend the horizon.
B15: Min score to qualify (0-100) | C15: =INDEX('Investor Personas'!$J$3:$J$6,Dash_Calc!$B$1) -> 40 | E15: =IF(D15="",C15,D15) -> 40
B16: Debt mix: 3Y G-Sec | C16: =INDEX(Dash_Calc!$B$44:$E$44,Dash_Calc!$B$1) -> 0 | E16: =IF(D16="",C16,D16) -> 0
B17: Debt mix: Reliance AAA NCD | C17: =INDEX(Dash_Calc!$B$45:$E$45,Dash_Calc!$B$1) -> 0 | E17: =IF(D17="",C17,D17) -> 0
B18: Debt mix: SMC A NCD | C18: =INDEX(Dash_Calc!$B$46:$E$46,Dash_Calc!$B$1) -> 1 | E18: =IF(D18="",C18,D18) -> 1
B19: Risk-free rate (10Y G-Sec) | C19: ='Investor Personas'!$C$13 -> 0.0735 | E19: =IF(D19="",C19,D19) -> 0.0735
B20: Equity risk premium | C20: ='Investor Personas'!$C$10 -> 0.07 | E20: =IF(D20="",C20,D20) -> 0.07
B21: Max score tilt (±) | C21: ='Investor Personas'!$C$12 -> 0.03 | E21: =IF(D21="",C21,D21) -> 0.03
B22: Segment split check | E22: =IF(ROUND(E11+E12+E13,4)=1,"✓ 100%","✗ "&TEXT(E11+E12+E13,"0%")) -> ✓ 100%
B23: FACTOR WEIGHTS (scoring) | C23: Preset | D23: Your override | E23: In use
B24: Market Cap | C24: =INDEX('Scoring Model'!$E$5:$H$5,Dash_Calc!$B$1) -> 0.07 | E24: =IF(D24="",C24,D24) -> 0.07
B25: Sales Growth YoY | C25: =INDEX('Scoring Model'!$E$6:$H$6,Dash_Calc!$B$1) -> 0.15 | E25: =IF(D25="",C25,D25) -> 0.15
B26: EPS Growth YoY | C26: =INDEX('Scoring Model'!$E$7:$H$7,Dash_Calc!$B$1) -> 0.16 | E26: =IF(D26="",C26,D26) -> 0.16
B27: ROE | C27: =INDEX('Scoring Model'!$E$8:$H$8,Dash_Calc!$B$1) -> 0.08 | E27: =IF(D27="",C27,D27) -> 0.08
B28: ROCE | C28: =INDEX('Scoring Model'!$E$9:$H$9,Dash_Calc!$B$1) -> 0.08 | E28: =IF(D28="",C28,D28) -> 0.08
B29: Trailing P/E | C29: =INDEX('Scoring Model'!$E$10:$H$10,Dash_Calc!$B$1) -> 0.04 | E29: =IF(D29="",C29,D29) -> 0.04
B30: PEG | C30: =INDEX('Scoring Model'!$E$11:$H$11,Dash_Calc!$B$1) -> 0.09 | E30: =IF(D30="",C30,D30) -> 0.09
B31: P/BV | C31: =INDEX('Scoring Model'!$E$12:$H$12,Dash_Calc!$B$1) -> 0.02 | E31: =IF(D31="",C31,D31) -> 0.02
B32: Beta | C32: =INDEX('Scoring Model'!$E$13:$H$13,Dash_Calc!$B$1) -> 0.03 | E32: =IF(D32="",C32,D32) -> 0.03
B33: Annualised SD | C33: =INDEX('Scoring Model'!$E$14:$H$14,Dash_Calc!$B$1) -> 0.03 | E33: =IF(D33="",C33,D33) -> 0.03
B34: Price vs 10M SMA | C34: =INDEX('Scoring Model'!$E$15:$H$15,Dash_Calc!$B$1) -> 0.09 | E34: =IF(D34="",C34,D34) -> 0.09
B35: 6M Momentum | C35: =INDEX('Scoring Model'!$E$16:$H$16,Dash_Calc!$B$1) -> 0.1 | E35: =IF(D35="",C35,D35) -> 0.1
B36: Debt / Equity | C36: =INDEX('Scoring Model'!$E$17:$H$17,Dash_Calc!$B$1) -> 0.06 | E36: =IF(D36="",C36,D36) -> 0.06
B37: Total weight (auto-normalised) | C37: =SUM(C24:C36) -> 1 | D37: =IF(ROUND(E37,4)=1,"✓","rescaled") -> ✓ | E37: =SUM(E24:E36) -> 1
B38: Tip: clear a yellow cell to go back to the preset. Weights that don't add to 100% are rescaled automatically.
B40: ASSET MIX | C40: Weight | D40: ₹ Invested
B41: Large Cap | C41: =Dash_Calc!E22 -> 0.3785887 | D41: =C41*$E$7 -> 3785887
B42: Mid Cap | C42: =Dash_Calc!E23 -> 0.33227356 | D42: =C42*$E$7 -> 3322735.6
...

Sheet Master Fund Sheet
A1: S.No | B1: Type of Asset | C1: Asset Name | D1: Company | E1: Industry | F1: Price 30-Sep-2021 | G1: Price 31-Dec-2025 | H1: Price 31-Jul-2026 | I1: Current Price 14-Oct-2026 | J1: Change Since 1 Aug | K1: % Change in 2026 | L1: % Change since Sep-2021 | M1: CAGR 5Y | N1: CAGR 3Y | O1: CAGR 1Y | P1: Market Cap (₹ Cr) | Q1: EPS (TTM) | R1: Trailing P/E | S1: ROCE | T1: ROE | U1: Book Value / Share | V1: P/BV | W1: Sales Growth YoY | X1: EPS Growth YoY | Y1: Profit CAGR 3Y | Z1: PEG | AA1: Debt / Equity | AB1: Dividend Yield | AC1: 10M SMA | AD1: Price vs 10M SMA | AE1: 6M Momentum | AF1: Trend Signal | AG1: EPS FY25 | AH1: EPS FY26 | AI1: Data Source / Note
A2: 1 | B2: =IF(P2>=100000,"Large Cap",IF(P2>=30000,"Mid Cap","Small Cap")) -> Large Cap | C2: RELIANCE | D2: Reliance Industries Ltd | E2: Oil & Gas / Conglomerate | F2: =Price_Data!B2 -> 1141.01 | G2: =Price_Data!B53 -> 1563.17 | H2: =Price_Data!B60 -> 1307.8 | I2: 1174.6 | J2: =IFERROR((I2-H2)/H2,"N/A") -> -0.10185044 | K2: =IFERROR((I2-G2)/G2,"N/A") -> -0.24857821 | L2: =IFERROR((I2-F2)/F2,"N/A") -> 0.029438831 | M2: =(Price_Data!B62/Price_Data!B2)^(1/5)-1 -> 0.0079343677 | N2: =(Price_Data!B62/Price_Data!B26)^(1/3)-1 -> 0.008125217 | O2: =Price_Data!B62/Price_Data!B50-1 -> -0.12574021 | P2: 1591358 | Q2: 55.22 | R2: =IF(Q2>0,I2/Q2,"N/A") -> 21.271279 | S2: 0.103 | T2: 0.0891 | U2: 668 | V2: =I2/U2 -> 1.7583832 | W2: 0.15 | X2: =IF(AG2>0,AH2/AG2-1,"N/A") -> 0.15970468 | Y2: 0.05 | Z2: =IF(AND(Y2>0,ISNUMBER(R2)),R2/(Y2*100),"N/A") -> 4.2542557 | AA2: 0.446 | AB2: 0.0051 | AC2: =AVERAGE(Price_Data!B53:B62) -> 1348.238 | AD2: =I2/AC2-1 -> -0.12878883 | AE2: =Price_Data!B62/Price_Data!B56-1 -> -0.11266268 | AF2: =IF(AD2>0,"Uptrend","Downtrend") -> Downtrend | AG2: 51.47 | AH2: 59.69 | AI2: Screener (consolidated), 14-Oct-2026
A3: 2 | B3: =IF(P3>=100000,"Large Cap",IF(P3>=30000,"Mid Cap","Small Cap")) -> Large Cap | C3: HDFCBANK | D3: HDFC Bank Ltd | E3: Private Sector Banking | F3: =Price_Data!C2 -> 746.28 | G3: =Price_Data!C53 -> 975.07 | H3: =Price_Data!C60 -> 748.15 | I3: 710.7 | J3: =IFERROR((I3-H3)/H3,"N/A") -> -0.050056807 | K3: =IFERROR((I3-G3)/G3,"N/A") -> -0.27112925 | L3: =IFERROR((I3-F3)/F3,"N/A") -> -0.047676475 | M3: =(Price_Data!C62/Price_Data!C2)^(1/5)-1 -> -0.010280502 | N3: =(Price_Data!C62/Price_Data!C26)^(1/3)-1 -> -0.010156542 | O3: =Price_Data!C62/Price_Data!C50-1 -> -0.24246149 | P3: 1095493 | Q3: 51.35 | R3: =IF(Q3>0,I3/Q3,"N/A") -> 13.840312 | S3: 0.0702 | T3: 0.136 | U3: 390 | V3: =I3/U3 -> 1.8223077 | W3: 0.03 | X3: =IF(AG3>0,AH3/AG3-1,"N/A") -> 0.067661046 | Y3: 0.18 | Z3: =IF(AND(Y3>0,ISNUMBER(R3)),R3/(Y3*100),"N/A") -> 0.7689062 | AA3: Bank | AB3: 0.0183 | AC3: =AVERAGE(Price_Data!C53:C62) -> 793.754 | AD3: =I3/AC3-1 -> -0.10463443 | AE3: =Price_Data!C62/Price_Data!C56-1 -> -0.01521573 | AF3: =IF(AD3>0,"Uptrend","Downtrend") -> Downtrend | AG3: 46.26 | AH3: 49.39 | AI3: Screener (consolidated), 14-Oct-2026. D/E not meaningful for a bank (deposits/borrowings are raw material) - scored neutral.
A4: 3 | B4: =IF(P4>=100000,"Large Cap",IF(P4>=30000,"Mid Cap","Small Cap")) -> Large Cap | C4: INFY | D4: Infosys Ltd | E4: IT Services | F4: =Price_Data!D2 -> 1459.05 | G4: =Price_Data!D53 -> 1581.18 | H4: =Price_Data!D60 -> 1130.1 | I4: 1088 | J4: =IFERROR((I4-H4)/H4,"N/A") -> -0.03725334 | K4: =IFERROR((I4-G4)/G4,"N/A") -> -0.3119063 | L4: =IFERROR((I4-F4)/F4,"N/A") -> -0.25430931 | M4: =(Price_Data!D62/Price_Data!D2)^(1/5)-1 -> -0.073869942 | N4: =(Price_Data!D62/Price_Data!D26)^(1/3)-1 -> -0.086931434 | O4: =Price_Data!D62/Price_Data!D50-1 -> -0.28480985 | P4: 441499 | Q4: 74.25 | R4: =IF(Q4>0,I4/Q4,"N/A") -> 14.653199 | S4: 0.4 | T4: 0.319 | U4: 225 | V4: =I4/U4 -> 4.8355556 | W4: 0.11 | X4: =IF(AG4>0,AH4/AG4-1,"N/A") -> 0.12857587 | Y4: 0.08 | Z4: =IF(AND(Y4>0,ISNUMBER(R4)),R4/(Y4*100),"N/A") -> 1.8316498 | AA4: 0.099 | AB4: 0.0441 | AC4: =AVERAGE(Price_Data!D53:D62) -> 1223.557 | AD4: =I4/AC4-1 -> -0.11078928 | AE4: =Price_Data!D62/Price_Data!D56-1 -> -0.18789978 | AF4: =IF(AD4>0,"Uptrend","Downtrend") -> Downtrend | AG4: 64.32 | AH4: 72.59 | AI4: Screener (consolidated), 14-Oct-2026
A5: 4 | B5: =IF(P5>=100000,"Large Cap",IF(P5>=30000,"Mid Cap","Small Cap")) -> Large Cap | C5: ITC | D5: ITC Ltd | E5: FMCG (Cigarettes, Foods, Agri) | F5: =Price_Data!E2 -> 185.94 | G5: =Price_Data!E53 -> 384.26 | H5: =Price_Data!E60 -> 281 | I5: 261.5 | J5: =IFERROR((I5-H5)/H5,"N/A") -> -0.069395018 | K5: =IFERROR((I5-G5)/G5,"N/A") -> -0.31947119 | L5: =IFERROR((I5-F5)/F5,"N/A") -> 0.40636765 | M5: =(Price_Data!E62/Price_Data!E2)^(1/5)-1 -> 0.071603145 | N5: =(Price_Data!E62/Price_Data!E26)^(1/3)-1 -> -0.11684886 | O5: =Price_Data!E62/Price_Data!E50-1 -> -0.31375366 | P5: 327297 | Q5: 15.84 | R5: =IF(Q5>0,I5/Q5,"N/A") -> 16.508838 | S5: 0.389 | T5: 0.293 | U5: 57.9 | V5: =I5/U5 -> 4.5164076 | W5: -0.03 | X5: =IF(AG5>0,AH5/AG5-1,"N/A") -> -0.40547353 | Y5: 0.03 | Z5: =IF(AND(Y5>0,ISNUMBER(R5)),R5/(Y5*100),"N/A") -> 5.5029461 | AA5: 0.033 | AB5: 0.0555 | AC5: =AVERAGE(Price_Data!E53:E62) -> 295.643 | AD5: =I5/AC5-1 -> -0.11548726 | AE5: =Price_Data!E62/Price_Data!E56-1 -> -0.061841682 | AF5: =IF(AD5>0,"Uptrend","Downtrend") -> Downtrend | AG5: 27.77 | AH5: 16.51 | AI5: Screener (consolidated), 14-Oct-2026. FY25 EPS inflated by one-time hotel-demerger gain, so YoY EPS growth is negative.
A6: 5 | B6: =IF(P6>=100000,"Large Cap",IF(P6>=30000,"Mid Cap","Small Cap")) -> Large Cap | C6: SUNPHARMA | D6: Sun Pharmaceutical Industries Ltd | E6: Pharmaceuticals | F6: =Price_Data!F2 -> 778.82 | G6: =Price_Data!F53 -> 1704.14 | H6: =Price_Data!F60 -> 1990.5 | I6: 1746.4 | J6: =IFERROR((I6-H6)/H6,"N/A") -> -0.1226325 | K6: =IFERROR((I6-G6)/G6,"N/A") -> 0.024798432 | L6: =IFERROR((I6-F6)/F6,"N/A") -> 1.2423667 | M6: =(Price_Data!F62/Price_Data!F2)^(1/5)-1 -> 0.18458013 | N6: =(Price_Data!F62/Price_Data!F26)^(1/3)-1 -> 0.17231688 | O6: =Price_Data!F62/Price_Data!F50-1 -> 0.14984144 | P6: 419399 | Q6: 50.41 | R6: =IF(Q6>0,I6/Q6,"N/A") -> 34.64392 | S6: 0.205 | T6: 0.16 | U6: 348 | V6: =I6/U6 -> 5.0183908 | W6: 0.11 | X6: =IF(AG6>0,AH6/AG6-1,"N/A") -> 0.050274424 | Y6: 0.13 | Z6: =IF(AND(Y6>0,ISNUMBER(R6)),R6/(Y6*100),"N/A") -> 2.6649169 | AA6: 0.055 | AB6: 0.0092 | AC6: =AVERAGE(Price_Data!F53:F62) -> 1801.767 | AD6: =I6/AC6-1 -> -0.030729279 | AE6: =Price_Data!F62/Price_Data!F56-1 -> 0.03651126 | AF6: =IF(AD6>0,"Uptrend","Downtrend") -> Downtrend | AG6: 45.55 | AH6: 47.84 | AI6: Screener (consolidated), 14-Oct-2026
A7: 6 | B7: =IF(P7>=100000,"Large Cap",IF(P7>=30000,"Mid Cap","Small Cap")) -> Large Cap | C7: MARUTI | D7: Maruti Suzuki India Ltd | E7: Automobiles (Passenger Vehicles) | F7: =Price_Data!G2 -> 7007.53 | G7: =Price_Data!G53 -> 16530.98 | H7: =Price_Data!G60 -> 14092.47 | I7: 11178 | J7: =IFERROR((I7-H7)/H7,"N/A") -> -0.20681045 | K7: =IFERROR((I7-G7)/G7,"N/A") -> -0.32381504 | L7: =IFERROR((I7-F7)/F7,"N/A") -> 0.59514123 | M7: =(Price_Data!G62/Price_Data!G2)^(1/5)-1 -> 0.11297156 | N7: =(Price_Data!G62/Price_Data!G26)^(1/3)-1 -> 0.051431807 | O7: =Price_Data!G62/Price_Data!G50-1 -> -0.24591767 | P7: 351130 | Q7: 455.91 | R7: =IF(Q7>0,I7/Q7,"N/A") -> 24.517997 | S7: 0.189 | T7: 0.143 | U7: 3408 | V7: =I7/U7 -> 3.2799296 | W7: 0.27 | X7: =IF(AG7>0,AH7/AG7-1,"N/A") -> 0.012359063 | Y7: 0.21 | Z7: =IF(AND(Y7>0,ISNUMBER(R7)),R7/(Y7*100),"N/A") -> 1.1675237 | AA7: 0.001 | AB7: 0.0125 | AC7: =AVERAGE(Price_Data!G53:G62) -> 13763.695 | AD7: =I7/AC7-1 -> -0.18786343 | AE7: =Price_Data!G62/Price_Data!G56-1 -> -0.017781221 | AF7: =IF(AD7>0,"Uptrend","Downtrend") -> Downtrend | AG7: 461.2 | AH7: 466.9 | AI7: Screener (consolidated), 14-Oct-2026
A8: 7 | B8: =IF(P8>=100000,"Large Cap",IF(P8>=30000,"Mid Cap","Small Cap")) -> Large Cap | C8: TATASTEEL | D8: Tata Steel Ltd | E8: Metals & Mining (Steel) | F8: =Price_Data!H2 -> 111.15 | G8: =Price_Data!H53 -> 176.44 | H8: =Price_Data!H60 -> 189.69 | I8: 174.49 | J8: =IFERROR((I8-H8)/H8,"N/A") -> -0.08013074 | K8: =IFERROR((I8-G8)/G8,"N/A") -> -0.011051916 | L8: =IFERROR((I8-F8)/F8,"N/A") -> 0.56986055 | M8: =(Price_Data!H62/Price_Data!H2)^(1/5)-1 -> 0.10642804 | N8: =(Price_Data!H62/Price_Data!H26)^(1/3)-1 -> 0.15063413 | O8: =Price_Data!H62/Price_Data!H50-1 -> 0.11453798 | P8: 217962 | Q8: 8.83 | R8: =IF(Q8>0,I8/Q8,"N/A") -> 19.761042 | S8: 0.125 | T8: 0.117 | U8: 81.8 | V8: =I8/U8 -> 2.1331296 | W8: 0.11 | X8: =IF(AG8>0,AH8/AG8-1,"N/A") -> 2.1569343 | Y8: 0.1 | Z8: =IF(AND(Y8>0,ISNUMBER(R8)),R8/(Y8*100),"N/A") -> 1.9761042 | AA8: 0.904 | AB8: 0.0229 | AC8: =AVERAGE(Price_Data!H53:H62) -> 191.9 | AD8: =I8/AC8-1 -> -0.090724336 | AE8: =Price_Data!H62/Price_Data!H56-1 -> -0.019576551 | AF8: =IF(AD8>0,"Uptrend","Downtrend") -> Downtrend | AG8: 2.74 | AH8: 8.65 | AI8: Screener (consolidated), 14-Oct-2026. FY24 loss -> FY26 EPS growth flattered by low base.
A9: 8 | B9: =IF(P9>=100000,"Large Cap",IF(P9>=30000,"Mid Cap","Small Cap")) -> Mid Cap | C9: DABUR | D9: Dabur India Ltd | E9: Personal Care & Ayurveda | F9: =Price_Data!I2 -> 580.63 | G9: =Price_Data!I53 -> 497.15 | H9: =Price_Data!I60 -> 421.45 | I9: 388.4 | J9: =IFERROR((I9-H9)/H9,"N/A") -> -0.078419741 | K9: =IFERROR((I9-G9)/G9,"N/A") -> -0.21874686 | L9: =IFERROR((I9-F9)/F9,"N/A") -> -0.33107142 | M9: =(Price_Data!I62/Price_Data!I2)^(1/5)-1 -> -0.081245076 | N9: =(Price_Data!I62/Price_Data!I26)^(1/3)-1 -> -0.10406588 | O9: =Price_Data!I62/Price_Data!I50-1 -> -0.21216267 | P9: 68960 | Q9: 11.11 | R9: =IF(Q9>0,I9/Q9,"N/A") -> 34.959496 | S9: 0.165 | T9: 0.1624 | U9: 64.38 | V9: =I9/U9 -> 6.0329295 | W9: 0.074 | X9: =IF(AG9>0,AH9/AG9-1,"N/A") -> 0.071356784 | Y9: 0.037 | Z9: =IF(AND(Y9>0,ISNUMBER(R9)),R9/(Y9*100),"N/A") -> 9.4485124 | AA9: 0.11 | AB9: 0.0203 | AC9: =AVERAGE(Price_Data!I53:I62) -> 438.722 | AD9: =I9/AC9-1 -> -0.11470134 | AE9: =Price_Data!I62/Price_Data!I56-1 -> -0.061921568 | AF9: =IF(AD9>0,"Uptrend","Downtrend") -> Downtrend | AG9: 9.95 | AH9: 10.66 | AI9: Stockanalysis.com (TTM Jun-2026; FY26 ratios) - Screener cache was stale. Mkt cap = 177.55 Cr shares x 14-Oct price. Profit CAGR 3Y = FY23 Rs1,701 Cr -> FY26 Rs1,895 Cr.
A10: 9 | B10: =IF(P10>=100000,"Large Cap",IF(P10>=30000,"Mid Cap","Small Cap")) -> Mid Cap | C10: ASTRAL | D10: Astral Ltd | E10: Building Materials (Pipes) | F10: =Price_Data!J2 -> 1603.58 | G10: =Price_Data!J53 -> 1386.32 | H10: =Price_Data!J60 -> 1446.33 | I10: 1443.2 | J10: =IFERROR((I10-H10)/H10,"N/A") -> -0.0021640981 | K10: =IFERROR((I10-G10)/G10,"N/A") -> 0.041029488 | L10: =IFERROR((I10-F10)/F10,"N/A") -> -0.10001372 | M10: =(Price_Data!J62/Price_Data!J2)^(1/5)-1 -> -0.030938491 | N10: =(Price_Data!J62/Price_Data!J26)^(1/3)-1 -> -0.10299846 | O10: =Price_Data!J62/Price_Data!J50-1 -> 0.0054660846 | P10: 38943 | Q10: 21.43 | R10: =IF(Q10>0,I10/Q10,"N/A") -> 67.344844 | S10: 0.192 | T10: 0.138 | U10: 151 | V10: =I10/U10 -> 9.5576159 | W10: 0.17 | X10: =IF(AG10>0,AH10/AG10-1,"N/A") -> 0.024102564 | Y10: 0.06 | Z10: =IF(AND(Y10>0,ISNUMBER(R10)),R10/(Y10*100),"N/A") -> 11.224141 | AA10: 0.062 | AB10: 0.0028 | AC10: =AVERAGE(Price_Data!J53:J62) -> 1489.782 | AD10: =I10/AC10-1 -> -0.031267662 | AE10: =Price_Data!J62/Price_Data!J56-1 -> -0.14161692 | AF10: =IF(AD10>0,"Uptrend","Downtrend") -> Downtrend | AG10: 19.5 | AH10: 19.97 | AI10: Screener (consolidated), 14-Oct-2026
A11: 10 | B11: =IF(P11>=100000,"Large Cap",IF(P11>=30000,"Mid Cap","Small Cap")) -> Mid Cap | C11: KEI | D11: KEI Industries Ltd | E11: Electricals (Cables & Wires) | F11: =Price_Data!K2 -> 920.36 | G11: =Price_Data!K53 -> 4454.93 | H11: =Price_Data!K60 -> 4999 | I11: 4648 | J11: =IFERROR((I11-H11)/H11,"N/A") -> -0.070214043 | K11: =IFERROR((I11-G11)/G11,"N/A") -> 0.043338504 | L11: =IFERROR((I11-F11)/F11,"N/A") -> 4.0501977 | M11: =(Price_Data!K62/Price_Data!K2)^(1/5)-1 -> 0.37081231 | N11: =(Price_Data!K62/Price_Data!K26)^(1/3)-1 -> 0.18985111 | O11: =Price_Data!K62/Price_Data!K50-1 -> 0.097966728 | P11: 44393 | Q11: 104.28 | R11: =IF(Q11>0,I11/Q11,"N/A") -> 44.572305 | S11: 0.2 | T11: 0.147 | U11: 697 | V11: =I11/U11 -> 6.6685796 | W11: 0.2 | X11: =IF(AG11>0,AH11/AG11-1,"N/A") -> 0.31819429 | Y11: 0.24 | Z11: =IF(AND(Y11>0,ISNUMBER(R11)),R11/(Y11*100),"N/A") -> 1.8571794 | AA11: 0.038 | AB11: 0.001 | AC11: =AVERAGE(Price_Data!K53:K62) -> 4834.123 | AD11: =I11/AC11-1 -> -0.038501916 | AE11: =Price_Data!K62/Price_Data!K56-1 -> 0.10326895 | AF11: =IF(AD11>0,"Uptrend","Downtrend") -> Downtrend | AG11: 72.88 | AH11: 96.07 | AI11: Screener (consolidated), 14-Oct-2026
A12: 11 | B12: =IF(P12>=100000,"Large Cap",IF(P12>=30000,"Mid Cap","Small Cap")) -> Small Cap | C12: BATAINDIA | D12: Bata India Ltd | E12: Footwear & Retail | F12: =Price_Data!L2 -> 1601.42 | G12: =Price_Data!L53 -> 899.98 | H12: =Price_Data!L60 -> 673.04 | I12: 619.35 | J12: =IFERROR((I12-H12)/H12,"N/A") -> -0.079772376 | K12: =IFERROR((I12-G12)/G12,"N/A") -> -0.31181804 | L12: =IFERROR((I12-F12)/F12,"N/A") -> -0.61324949 | M12: =(Price_Data!L62/Price_Data!L2)^(1/5)-1 -> -0.1731971 | N12: =(Price_Data!L62/Price_Data!L26)^(1/3)-1 -> -0.25578406 | O12: =Price_Data!L62/Price_Data!L50-1 -> -0.44349508 | P12: 7960 | Q12: 10.44 | R12: =IF(Q12>0,I12/Q12,"N/A") -> 59.324713 | S12: 0.113 | T12: 0.0847 | U12: 124.14 | V12: =I12/U12 -> 4.9891252 | W12: 0.0077 | X12: =IF(AG12>0,AH12/AG12-1,"N/A") -> -0.59424796 | Y12: -0.25 | Z12: =IF(AND(Y12>0,ISNUMBER(R12)),R12/(Y12*100),"N/A") -> N/A | AA12: 0.87 | AB12: 0.0145 | AC12: =AVERAGE(Price_Data!L53:L62) -> 700.465 | AD12: =I12/AC12-1 -> -0.11580165 | AE12: =Price_Data!L62/Price_Data!L56-1 -> 0.067215151 | AF12: =IF(AD12>0,"Uptrend","Downtrend") -> Downtrend | AG12: 25.73 | AH12: 10.44 | AI12: Stockanalysis.com (FY26, updated Aug-2026). Mkt cap = 12.85 Cr shares x 14-Oct price. D/E includes lease liabilities.
A13: 12 | B13: =IF(P13>=100000,"Large Cap",IF(P13>=30000,"Mid Cap","Small Cap")) -> Small Cap | C13: ZEEL | D13: Zee Entertainment Enterprises Ltd | E13: Media & Entertainment | F13: =Price_Data!M2 -> 284.62 | G13: =Price_Data!M53 -> 87.86 | H13: =Price_Data!M60 -> 111.88 | I13: 73.81 | J13: =IFERROR((I13-H13)/H13,"N/A") -> -0.34027529 | K13: =IFERROR((I13-G13)/G13,"N/A") -> -0.1599135 | L13: =IFERROR((I13-F13)/F13,"N/A") -> -0.74067177 | M13: =(Price_Data!M62/Price_Data!M2)^(1/5)-1 -> -0.23520826 | N13: =(Price_Data!M62/Price_Data!M26)^(1/3)-1 -> -0.33307119 | O13: =Price_Data!M62/Price_Data!M50-1 -> -0.32145786 | P13: 7089 | Q13: 2.13 | R13: =IF(Q13>0,I13/Q13,"N/A") -> 34.652582 | S13: 0.011 | T13: 0.0233 | U13: 121 | V13: =I13/U13 -> 0.61 | W13: 0.0242 | X13: =IF(AG13>0,AH13/AG13-1,"N/A") -> -0.59830269 | Y13: 0.04 | Z13: =IF(AND(Y13>0,ISNUMBER(R13)),R13/(Y13*100),"N/A") -> 8.6631455 | AA13: 0.02 | AB13: 0.027 | AC13: =AVERAGE(Price_Data!M53:M62) -> 88.357 | AD13: =I13/AC13-1 -> -0.16463891 | AE13: =Price_Data!M62/Price_Data!M56-1 -> 0.056911723 | AF13: =IF(AD13>0,"Uptrend","Downtrend") -> Downtrend | AG13: 7.07 | AH13: 2.84 | AI13: Stockanalysis.com (TTM Jun-2026). FY23 profit base was abnormally low, so 5Y profit CAGR (4%, Screener) is used for PEG.
A14: 13 | B14: =IF(P14>=100000,"Large Cap",IF(P14>=30000,"Mid Cap","Small Cap")) -> Small Cap | C14: JUSTDIAL | D14: Just Dial Ltd | E14: Internet / Local Search Services | F14: =Price_Data!N2 -> 989.2 | G14: =Price_Data!N53 -> 725.3 | H14: =Price_Data!N60 -> 716.7 | I14: 682.75 | J14: =IFERROR((I14-H14)/H14,"N/A") -> -0.04736989 | K14: =IFERROR((I14-G14)/G14,"N/A") -> -0.05866538 | L14: =IFERROR((I14-F14)/F14,"N/A") -> -0.30979579 | M14: =(Price_Data!N62/Price_Data!N2)^(1/5)-1 -> -0.076030608 | N14: =(Price_Data!N62/Price_Data!N26)^(1/3)-1 -> -0.029783273 | O14: =Price_Data!N62/Price_Data!N50-1 -> -0.19663531 | P14: 5807 | Q14: 59.21 | R14: =IF(Q14>0,I14/Q14,"N/A") -> 11.530991 | S14: 0.058 | T14: 0.1023 | U14: 601 | V14: =I14/U14 -> 1.1360233 | W14: 0.0727 | X14: =IF(AG14>0,AH14/AG14-1,"N/A") -> -0.14922114 | Y14: 0.45 | Z14: =IF(AND(Y14>0,ISNUMBER(R14)),R14/(Y14*100),"N/A") -> 0.25624425 | AA14: 0.02 | AB14: 0 | AC14: =AVERAGE(Price_Data!N53:N62) -> 610.325 | AD14: =I14/AC14-1 -> 0.11866628 | AE14: =Price_Data!N62/Price_Data!N56-1 -> 0.35755044 | AF14: =IF(AD14>0,"Uptrend","Downtrend") -> Uptrend | AG14: 68.69 | AH14: 58.44 | AI14: Stockanalysis.com (TTM Jun-2026). Cash-rich balance sheet depresses ROCE. Mkt cap = 8.5 Cr shares x 14-Oct price.
A15: 14 | B15: =IF(P15>=100000,"Large Cap",IF(P15>=30000,"Mid Cap","Small Cap")) -> Small Cap | C15: EIHOTEL | D15: EIH Ltd (The Oberoi Group) | E15: Hotels & Hospitality | F15: =Price_Data!O2 -> 127.24 | G15: =Price_Data!O53 -> 366.59 | H15: =Price_Data!O60 -> 327 | I15: 291.95 | J15: =IFERROR((I15-H15)/H15,"N/A") -> -0.10718654 | K15: =IFERROR((I15-G15)/G15,"N/A") -> -0.20360621 | L15: =IFERROR((I15-F15)/F15,"N/A") -> 1.2944829 | M15: =(Price_Data!O62/Price_Data!O2)^(1/5)-1 -> 0.18800268 | N15: =(Price_Data!O62/Price_Data!O26)^(1/3)-1 -> 0.10933147 | O15: =Price_Data!O62/Price_Data!O50-1 -> -0.15957239 | P15: 18286 | Q15: 11.38 | R15: =IF(Q15>0,I15/Q15,"N/A") -> 25.654657 | S15: 0.207 | T15: 0.145 | U15: 84.2 | V15: =I15/U15 -> 3.4673397 | W15: 0.08 | X15: =IF(AG15>0,AH15/AG15-1,"N/A") -> -0.14974619 | Y15: 0.25 | Z15: =IF(AND(Y15>0,ISNUMBER(R15)),R15/(Y15*100),"N/A") -> 1.0261863 | AA15: 0.048 | AB15: 0.0051 | AC15: =AVERAGE(Price_Data!O53:O62) -> 310.578 | AD15: =I15/AC15-1 -> -0.059978492 | AE15: =Price_Data!O62/Price_Data!O56-1 -> 0.10572509 | AF15: =IF(AD15>0,"Uptrend","Downtrend") -> Downtrend | AG15: 11.82 | AH15: 10.05 | AI15: Screener (consolidated), 14-Oct-2026
A17: S.No | B17: Type of Asset | C17: Asset Name | D17: Instrument | E17: Security | F17: Coupon (p.a.) | G17: Rating | H17: Face Value / Unit (₹) | I17: Yield to Maturity | J17: Annual Default Prob. (assumed) | K17: Loss Given Default | L17: Expected Credit Loss | M17: Credit-Adjusted Return | N17: Source
A18: 15 | B18: Government Bond | C18: GSEC-3Y | D18: 3-Year Government of India Security | E18: Sovereign | F18: 0.0707 | G18: Sovereign (SOV) | H18: 100 | I18: 0.0707 | J18: 0 | K18: 0 | L18: =J18*K18 -> 0 | M18: =I18-L18 -> 0.0707 | N18: 3Y G-Sec yield 7.07% on 13-Oct-2026 (Trading Economics). Bought at par via RBI Retail Direct.
A19: 16 | B19: Corporate Bond | C19: RIL-NCD-2036 | D19: Reliance Industries 7.90% NCD (Oct-2036) | E19: Senior | F19: 0.079 | G19: CRISIL AAA / CARE AAA | H19: 100000 | I19: 0.079 | J19: 0.0005 | K19: 0.5 | L19: =J19*K19 -> 0.00025 | M19: =I19-L19 -> 0.07875 | N19: Rs13,008 Cr NCDs allotted 1-Oct-2026 at 7.90% (PSU Connect). Sold after 3 yrs; assumes flat yields.
A20: 17 | B20: Corporate Bond | C20: SMC-NCD-2029 | D20: SMC Global Securities NCD Series III (36M) | E20: Secured | F20: 0.0975 | G20: ICRA A (Stable) | H20: 1000 | I20: 0.0975 | J20: 0.006 | K20: 0.5 | L20: =J20*K20 -> 0.003 | M20: =I20-L20 -> 0.0945 | N20: Public issue 5-9 Oct 2026, 36-month annual-pay series (Chanakya Nipothi).
A22: S.No | B22: Type of Asset | C22: Asset Name | D22: Benchmark | F22: Price 30-Sep-2021 | G22: Price 31-Dec-2025 | H22: Price 31-Jul-2026 | I22: Current 14-Oct-2026 | J22: Change Since 1 Aug | K22: % Change in 2026 | L22: % Change since Sep-2021 | M22: CAGR 5Y | N22: CAGR 3Y | O22: CAGR 1Y
A23: 18 | B23: Index | C23: NIFTY_50 | D23: NIFTY 50 (^NSEI) | F23: =Price_Data!P2 -> 17618.15 | G23: =Price_Data!P53 -> 26129.6 | H23: =Price_Data!P60 -> 24383.6 | I23: 22622.7 | J23: =(I23-H23)/H23 -> -0.072216572 | K23: =(I23-G23)/G23 -> -0.13421178 | L23: =(I23-F23)/F23 -> 0.2840565 | M23: =(Price_Data!P62/Price_Data!P2)^(1/5)-1 -> 0.051255274 | N23: =(Price_Data!P62/Price_Data!P26)^(1/3)-1 -> 0.048252202 | O23: =Price_Data!P62/Price_Data!P50-1 -> -0.080884235
A25: Legend: blue = sourced input (Screener / Yahoo / Stockanalysis / RBI), black = formula, green = link to another sheet, yellow = live price to update. Cap segment is classified by formula: ≥ ₹1,00,000 Cr Large, ≥ ₹30,000 Cr Mid, else Small.

Sheet Portfolio_History
A1: Snapshot_Date | B1: Persona | C1: Asset_Ticker | D1: Asset_Class | E1: Cap_Sector | F1: Weight | G1: Allocated_Capital | H1: Live_Price | I1: Units_Held | J1: Beta | K1: Target_Price_2029 | L1: Exp_Annual_Return | M1: Current_Position_Value
A2: 46309 | B2: Vikram | C2: KEI | D2: Equity | E2: Mid Cap / Electricals (Cables & Wires) | F2: 0.14 | G2: 1400000 | H2: 4648 | I2: 301 | J2: 1.4331655 | K2: 7316.4879 | L2: 0.1632655 | M2: 1399048
A3: 46309 | B3: Vikram | C3: JUSTDIAL | D3: Equity | E3: Small Cap / Internet / Local Search Services | F3: 0.12 | G3: 1200000 | H3: 682.75 | I3: 1757 | J3: 1.2835508 | K3: 985.48313 | L3: 0.13013197 | M3: 1199591.8
A4: 46309 | B4: Vikram | C4: EIHOTEL | D4: Equity | E4: Small Cap / Hotels & Hospitality | F4: 0.12 | G4: 1200000 | H4: 291.95 | I4: 4110 | J4: 1.1041444 | K4: 434.59503 | L4: 0.1418054 | M4: 1199914.5
A5: 46309 | B5: Vikram | C5: ASTRAL | D5: Equity | E5: Mid Cap / Building Materials (Pipes) | F5: 0.1 | G5: 1000000 | H5: 1443.2 | I5: 692 | J5: 0.69741418 | K5: 1999.6182 | L5: 0.1148254 | M5: 998694.4
A6: 46309 | B6: Vikram | C6: DABUR | D6: Equity | E6: Mid Cap / Personal Care & Ayurveda | F6: 0.09 | G6: 900000 | H6: 388.4 | I6: 2317 | J6: 0.869804 | K6: 514.98095 | L6: 0.098594228 | M6: 899922.8
A7: 46309 | B7: Vikram | C7: HDFCBANK | D7: Equity | E7: Large Cap / Private Sector Banking | F7: 0.06 | G7: 600000 | H7: 710.7 | I7: 844 | J7: 0.884506 | K7: 1033.7935 | L7: 0.13305021 | M7: 599830.8
A8: 46309 | B8: Vikram | C8: INFY | D8: Equity | E8: Large Cap / IT Services | F8: 0.06 | G8: 600000 | H8: 1088 | I8: 551 | J8: 0.75751049 | K8: 1662.3139 | L8: 0.15175839 | M8: 599488
A9: 46309 | B9: Vikram | C9: SUNPHARMA | D9: Equity | E9: Large Cap / Pharmaceuticals | F9: 0.06 | G9: 600000 | H9: 1746.4 | I9: 343 | J9: 0.87112781 | K9: 2536.9164 | L9: 0.13254155 | M9: 599015.2
A10: 46309 | B10: Vikram | C10: MARUTI | D10: Equity | E10: Large Cap / Automobiles (Passenger Vehicles) | F10: 0.06 | G10: 600000 | H10: 11178 | I10: 53 | J10: 0.68561437 | K10: 15934.448 | L10: 0.12544508 | M10: 592434
A11: 46309 | B11: Vikram | C11: RELIANCE | D11: Equity | E11: Large Cap / Oil & Gas / Conglomerate | F11: 0.05 | G11: 500000 | H11: 1174.6 | I11: 425 | J11: 0.99084157 | K11: 1634.2499 | L11: 0.11637344 | M11: 499205
A12: 46309 | B12: Vikram | C12: TATASTEEL | D12: Equity | E12: Large Cap / Metals & Mining (Steel) | F12: 0.05 | G12: 500000 | H12: 174.49 | I12: 2865 | J12: 1.1923044 | K12: 246.76838 | L12: 0.12246547 | M12: 499913.85
A13: 46309 | B13: Vikram | C13: ITC | D13: Equity | E13: Large Cap / FMCG (Cigarettes, Foods, Agri) | F13: 0.04 | G13: 400000 | H13: 261.5 | I13: 1529 | J13: 0.81842432 | K13: 353.57666 | L13: 0.10578484 | M13: 399833.5
... A56: 46309 | B56: Meera | C56: SMC-NCD-2029 | D56: Bonds | E56: ICRA A (Stable) / Corporate Bond | F56: 0.1 | G56: 1000000 | H56: 1000 | I56: 1000 | J56: 0 | K56: 1311.1347 | L56: 0.0945 | M56: 1000000
A58: Entry snapshot at the 14-Oct-2026 close. Append a new block of rows (same columns) at each review date with that day's prices to build the daily/weekly history.

Sheet Vikram
A1: Asset / Ticker | B1: Asset Class | C1: Cap / Sector | D1: Investor Score | E1: Weight | F1: Capital (₹) | G1: Current Price (₹) | H1: Units | I1: Invested (₹) | J1: Beta | K1: Exp. Annual Return | L1: Target Price Oct-2029 (₹) | M1: Value Oct-2029 (₹)
A2: KEI | B2: Equity | C2: ='Master Fund Sheet'!B11&" / "&'Master Fund Sheet'!E11 -> Mid Cap / Electricals (Cables & Wires) | D2: ='Scoring Model'!AD32 -> 68.480769 | E2: 0.14 | F2: =E2*'Investor Personas'!$C$1 -> 1400000 | G2: =IFERROR(INDEX('Master Fund Sheet'!$I$2:$I$15,MATCH(A2,'Master Fund Sheet'!$C$2:$C$15,0)),0) -> 4648 | H2: =IF(G2>0,ROUNDDOWN(F2/G2,0),0) -> 301 | I2: =H2*G2 -> 1399048 | J2: =IFERROR(INDEX('Risk Metrics'!$G$2:$G$15,MATCH(A2,'Risk Metrics'!$A$2:$A$15,0)),0) -> 1.4331655 | K2: =IFERROR(INDEX('Scoring Model'!$AQ$23:$AQ$36,MATCH(A2,'Scoring Model'!$A$23:$A$36,0)),0) -> 0.1632655 | L2: =G2*(1+K2)^'Investor Personas'!$F$1 -> 7316.4879 | M2: =I2*(1+K2)^'Investor Personas'!$F$1 -> 2202262.9
A3: JUSTDIAL | B3: Equity | C3: ='Master Fund Sheet'!B14&" / "&'Master Fund Sheet'!E14 -> Small Cap / Internet / Local Search Services | D3: ='Scoring Model'!AD35 -> 51.307692 | E3: 0.12 | F3: =E3*'Investor Personas'!$C$1 -> 1200000 | G3: =IFERROR(INDEX('Master Fund Sheet'!$I$2:$I$15,MATCH(A3,'Master Fund Sheet'!$C$2:$C$15,0)),0) -> 682.75 | H3: =IF(G3>0,ROUNDDOWN(F3/G3,0),0) -> 1757 | I3: =H3*G3 -> 1199591.8 | J3: =IFERROR(INDEX('Risk Metrics'!$G$2:$G$15,MATCH(A3,'Risk Metrics'!$A$2:$A$15,0)),0) -> 1.2835508 | K3: =IFERROR(INDEX('Scoring Model'!$AQ$23:$AQ$36,MATCH(A3,'Scoring Model'!$A$23:$A$36,0)),0) -> 0.13013197 | L3: =G3*(1+K3)^'Investor Personas'!$F$1 -> 985.48313 | M3: =I3*(1+K3)^'Investor Personas'!$F$1 -> 1731493.9
A4: EIHOTEL | B4: Equity | C4: ='Master Fund Sheet'!B15&" / "&'Master Fund Sheet'!E15 -> Small Cap / Hotels & Hospitality | D4: ='Scoring Model'!AD36 -> 55.153846 | E4: 0.12 | F4: =E4*'Investor Personas'!$C$1 -> 1200000 | G4: =IFERROR(INDEX('Master Fund Sheet'!$I$2:$I$15,MATCH(A4,'Master Fund Sheet'!$C$2:$C$15,0)),0) -> 291.95 | H4: =IF(G4>0,ROUNDDOWN(F4/G4,0),0) -> 4110 | I4: =H4*G4 -> 1199914.5 | J4: =IFERROR(INDEX('Risk Metrics'!$G$2:$G$15,MATCH(A4,'Risk Metrics'!$A$2:$A$15,0)),0) -> 1.1041444 | K4: =IFERROR(INDEX('Scoring Model'!$AQ$23:$AQ$36,MATCH(A4,'Scoring Model'!$A$23:$A$36,0)),0) -> 0.1418054 | L4: =G4*(1+K4)^'Investor Personas'!$F$1 -> 434.59503 | M4: =I4*(1+K4)^'Investor Personas'!$F$1 -> 1786185.6
A5: ASTRAL | B5: Equity | C5: ='Master Fund Sheet'!B10&" / "&'Master Fund Sheet'!E10 -> Mid Cap / Building Materials (Pipes) | D5: ='Scoring Model'!AD31 -> 45.423077 | E5: 0.1 | F5: =E5*'Investor Personas'!$C$1 -> 1000000 | G5: =IFERROR(INDEX('Master Fund Sheet'!$I$2:$I$15,MATCH(A5,'Master Fund Sheet'!$C$2:$C$15,0)),0) -> 1443.2 | H5: =IF(G5>0,ROUNDDOWN(F5/G5,0),0) -> 692 | I5: =H5*G5 -> 998694.4 | J5: =IFERROR(INDEX('Risk Metrics'!$G$2:$G$15,MATCH(A5,'Risk Metrics'!$A$2:$A$15,0)),0) -> 0.69741418 | K5: =IFERROR(INDEX('Scoring Model'!$AQ$23:$AQ$36,MATCH(A5,'Scoring Model'!$A$23:$A$36,0)),0) -> 0.1148254 | L5: =G5*(1+K5)^'Investor Personas'!$F$1 -> 1999.6182 | M5: =I5*(1+K5)^'Investor Personas'!$F$1 -> 1383735.8
A6: DABUR | B6: Equity | C6: ='Master Fund Sheet'!B9&" / "&'Master Fund Sheet'!E9 -> Mid Cap / Personal Care & Ayurveda | D6: ='Scoring Model'!AD30 -> 44.403846 | E6: 0.09 | F6: =E6*'Investor Personas'!$C$1 -> 900000 | G6: =IFERROR(INDEX('Master Fund Sheet'!$I$2:$I$15,MATCH(A6,'Master Fund Sheet'!$C$2:$C$15,0)),0) -> 388.4 | H6: =IF(G6>0,ROUNDDOWN(F6/G6,0),0) -> 2317 | I6: =H6*G6 -> 899922.8 | J6: =IFERROR(INDEX('Risk Metrics'!$G$2:$G$15,MATCH(A6,'Risk Metrics'!$A$2:$A$15,0)),0) -> 0.869804 | K6: =IFERROR(INDEX('Scoring Model'!$AQ$23:$AQ$36,MATCH(A6,'Scoring Model'!$A$23:$A$36,0)),0) -> 0.098594228 | L6: =G6*(1+K6)^'Investor Personas'!$F$1 -> 514.98095 | M6: =I6*(1+K6)^'Investor Personas'!$F$1 -> 1193210.9
A7: HDFCBANK | B7: Equity | C7: ='Master Fund Sheet'!B3&" / "&'Master Fund Sheet'!E3 -> Large Cap / Private Sector Banking | D7: ='Scoring Model'!AD24 -> 55.403846 | E7: 0.06 | F7: =E7*'Investor Personas'!$C$1 -> 600000 | G7: =IFERROR(INDEX('Master Fund Sheet'!$I$2:$I$15,MATCH(A7,'Master Fund Sheet'!$C$2:$C$15,0)),0) -> 710.7 | H7: =IF(G7>0,ROUNDDOWN(F7/G7,0),0) -> 844 | I7: =H7*G7 -> 599830.8 | J7: =IFERROR(INDEX('Risk Metrics'!$G$2:$G$15,MATCH(A7,'Risk Metrics'!$A$2:$A$15,0)),0) -> 0.884506 | K7: =IFERROR(INDEX('Scoring Model'!$AQ$23:$AQ$36,MATCH(A7,'Scoring Model'!$A$23:$A$36,0)),0) -> 0.13305021 | L7: =G7*(1+K7)^'Investor Personas'!$F$1 -> 1033.7935 | M7: =I7*(1+K7)^'Investor Personas'!$F$1 -> 872521.69
A8: INFY | B8: Equity | C8: ='Master Fund Sheet'!B4&" / "&'Master Fund Sheet'!E4 -> Large Cap / IT Services | D8: ='Scoring Model'!AD25 -> 62.538462 | E8: 0.06 | F8: =E8*'Investor Personas'!$C$1 -> 600000 | G8: =IFERROR(INDEX('Master Fund Sheet'!$I$2:$I$15,MATCH(A8,'Master Fund Sheet'!$C$2:$C$15,0)),0) -> 1088 | H8: =IF(G8>0,ROUNDDOWN(F8/G8,0),0) -> 551 | I8: =H8*G8 -> 599488 | J8: =IFERROR(INDEX('Risk Metrics'!$G$2:$G$15,MATCH(A8,'Risk Metrics'!$A$2:$A$15,0)),0) -> 0.75751049 | K8: =IFERROR(INDEX('Scoring Model'!$AQ$23:$AQ$36,MATCH(A8,'Scoring Model'!$A$23:$A$36,0)),0) -> 0.15175839 | L8: =G8*(1+K8)^'Investor Personas'!$F$1 -> 1662.3139 | M8: =I8*(1+K8)^'Investor Personas'!$F$1 -> 915934.97
A9: SUNPHARMA | B9: Equity | C9: ='Master Fund Sheet'!B6&" / "&'Master Fund Sheet'!E6 -> Large Cap / Pharmaceuticals | D9: ='Scoring Model'!AD27 -> 61.519231 | E9: 0.06 | F9: =E9*'Investor Personas'!$C$1 -> 600000 | G9: =IFERROR(INDEX('Master Fund Sheet'!$I$2:$I$15,MATCH(A9,'Master Fund Sheet'!$C$2:$C$15,0)),0) -> 1746.4 | H9: =IF(G9>0,ROUNDDOWN(F9/G9,0),0) -> 343 | I9: =H9*G9 -> 599015.2 | J9: =IFERROR(INDEX('Risk Metrics'!$G$2:$G$15,MATCH(A9,'Risk Metrics'!$A$2:$A$15,0)),0) -> 0.87112781 | K9: =IFERROR(INDEX('Scoring Model'!$AQ$23:$AQ$36,MATCH(A9,'Scoring Model'!$A$23:$A$36,0)),0) -> 0.13254155 | L9: =G9*(1+K9)^'Investor Personas'!$F$1 -> 2536.9164 | M9: =I9*(1+K9)^'Investor Personas'!$F$1 -> 870162.32
A10: MARUTI | B10: Equity | C10: ='Master Fund Sheet'!B7&" / "&'Master Fund Sheet'!E7 -> Large Cap / Automobiles (Passenger Vehicles) | D10: ='Scoring Model'!AD28 -> 60.211538 | E10: 0.06 | F10: =E10*'Investor Personas'!$C$1 -> 600000 | G10: =IFERROR(INDEX('Master Fund Sheet'!$I$2:$I$15,MATCH(A10,'Master Fund Sheet'!$C$2:$C$15,0)),0) -> 11178 | H10: =IF(G10>0,ROUNDDOWN(F10/G10,0),0) -> 53 | I10: =H10*G10 -> 592434 | J10: =IFERROR(INDEX('Risk Metrics'!$G$2:$G$15,MATCH(A10,'Risk Metrics'!$A$2:$A$15,0)),0) -> 0.68561437 | K10: =IFERROR(INDEX('Scoring Model'!$AQ$23:$AQ$36,MATCH(A10,'Scoring Model'!$A$23:$A$36,0)),0) -> 0.12544508 | L10: =G10*(1+K10)^'Investor Personas'!$F$1 -> 15934.448 | M10: =I10*(1+K10)^'Investor Personas'!$F$1 -> 844525.75
A11: RELIANCE | B11: Equity | C11: ='Master Fund Sheet'!B2&" / "&'Master Fund Sheet'!E2 -> Large Cap / Oil & Gas / Conglomerate | D11: ='Scoring Model'!AD23 -> 50.384615 | E11: 0.05 | F11: =E11*'Investor Personas'!$C$1 -> 500000 | G11: =IFERROR(INDEX('Master Fund Sheet'!$I$2:$I$15,MATCH(A11,'Master Fund Sheet'!$C$2:$C$15,0)),0) -> 1174.6 | H11: =IF(G11>0,ROUNDDOWN(F11/G11,0),0) -> 425 | I11: =H11*G11 -> 499205 | J11: =IFERROR(INDEX('Risk Metrics'!$G$2:$G$15,MATCH(A11,'Risk Metrics'!$A$2:$A$15,0)),0) -> 0.99084157 | K11: =IFERROR(INDEX('Scoring Model'!$AQ$23:$AQ$36,MATCH(A11,'Scoring Model'!$A$23:$A$36,0)),0) -> 0.11637344 | L11: =G11*(1+K11)^'Investor Personas'!$F$1 -> 1634.2499 | M11: =I11*(1+K11)^'Investor Personas'!$F$1 -> 694556.23
A12: TATASTEEL | B12: Equity | C12: ='Master Fund Sheet'!B8&" / "&'Master Fund Sheet'!E8 -> Large Cap / Metals & Mining (Steel) | D12: ='Scoring Model'!AD29 -> 53.5 | E12: 0.05 | F12: =E12*'Investor Personas'!$C$1 -> 500000 | G12: =IFERROR(INDEX('Master Fund Sheet'!$I$2:$I$15,MATCH(A12,'Master Fund Sheet'!$C$2:$C$15,0)),0) -> 174.49 | H12: =IF(G12>0,ROUNDDOWN(F12/G12,0),0) -> 2865 | I12: =H12*G12 -> 499913.85 | J12: =IFERROR(INDEX('Risk Metrics'!$G$2:$G$15,MATCH(A12,'Risk Metrics'!$A$2:$A$15,0)),0) -> 1.1923044 | K12: =IFERROR(INDEX('Scoring Model'!$AQ$23:$AQ$36,MATCH(A12,'Scoring Model'!$A$23:$A$36,0)),0) -> 0.12246547 | L12: =G12*(1+K12)^'Investor Personas'!$F$1 -> 246.76838 | M12: =I12*(1+K12)^'Investor Personas'!$F$1 -> 706991.41
A13: ITC | B13: Equity | C13: ='Master Fund Sheet'!B5&" / "&'Master Fund Sheet'!E5 -> Large Cap / FMCG (Cigarettes, Foods, Agri) | D13: ='Scoring Model'!AD26 -> 42.75 | E13: 0.04 | F13: =E13*'Investor Personas'!$C$1 -> 400000 | G13: =IFERROR(INDEX('Master Fund Sheet'!$I$2:$I$15,MATCH(A13,'Master Fund Sheet'!$C$2:$C$15,0)),0) -> 261.5 | H13: =IF(G13>0,ROUNDDOWN(F13/G13,0),0) -> 1529 | I13: =H13*G13 -> 399833.5 | J13: =IFERROR(INDEX('Risk Metrics'!$G$2:$G$15,MATCH(A13,'Risk Metrics'!$A$2:$A$15,0)),0) -> 0.81842432 | K13: =IFERROR(INDEX('Scoring Model'!$AQ$23:$AQ$36,MATCH(A13,'Scoring Model'!$A$23:$A$36,0)),0) -> 0.10578484 | L13: =G13*(1+K13)^'Investor Personas'!$F$1 -> 353.57666 | M13: =I13*(1+K13)^'Investor Personas'!$F$1 -> 540618.72
A14: SMC-NCD-2029 | B14: Bonds | C14: ='Master Fund Sheet'!G20&" / "&'Master Fund Sheet'!B20 -> ICRA A (Stable) / Corporate Bond | D14: — | E14: 0.05 | F14: =E14*'Investor Personas'!$C$1 -> 500000 | G14: ='Master Fund Sheet'!H20 -> 1000 | H14: =IF(G14>0,ROUNDDOWN(F14/G14,0),0) -> 500 | I14: =H14*G14 -> 500000 | J14: 0 | K14: ='Master Fund Sheet'!M20 -> 0.0945 | L14: =G14*(1+K14)^'Investor Personas'!$F$1 -> 1311.1347 | M14: =I14*(1+K14)^'Investor Personas'!$F$1 -> 655567.33
A16: TOTAL | E16: =SUM(E2:E14) -> 1 | F16: =SUM(F2:F14) -> 10000000 | H16: =COUNTIF(B2:B14,"Equity")&" stocks" -> 12 stocks | I16: =SUM(I2:I14) -> 9986891.8 | M16: =SUM(M2:M14) -> 14397767
A18: PORTFOLIO SUMMARY
A19: Corpus | B19: ='Investor Personas'!$C$1 -> 10000000 | D19: The Momentum Maverick · 31, start-up founder, no dependants. Chases the upper assignment target and tolerates deep drawdowns.
A20: Invested | B20: =I16 -> 9986891.8 | D20: Policy: 95% equity split 40/35/25 Large/Mid/Small; stocks need investor score ≥ 40 and beta ≤ 2.5; weight ∝ score within each segment, rounded to whole %.
A21: Uninvested cash (earns 3Y G-Sec yield) | B21: =B19-B20 -> 13108.2 | D21: Not selected: BATAINDIA, ZEEL
A22: Weighted portfolio beta | B22: =SUMPRODUCT(I2:I14,J2:J14)/B19 -> 0.96795318
A23: Projected value Oct-2029 | B23: =M16+B21*(1+'Master Fund Sheet'!$I$18)^'Investor Personas'!$F$1 -> 14413857
A24: Expected CAGR | B24: =(B23/B19)^(1/'Investor Personas'!$F$1)-1 -> 0.12960534
A25: Target | B25: ='Investor Personas'!C3 -> 21500000
A26: CAGR required | B26: ='Investor Personas'!D3 -> 0.29066288
A27: Surplus / (shortfall) | B27: =B23-B25 -> -7086143
A28: Portfolio SD (5Y history) | B28: ='Risk Metrics'!B91 -> 0.16173329
A29: Probability of reaching target | B29: =1-NORMSDIST((LN(B25/B19)-LN(1+B24)*'Investor Personas'!$F$1)/(B28*SQRT('Investor Personas'!$F$1))) -> 0.076729768

Sheet Ananya
A1: Asset / Ticker | B1: Asset Class | C1: Cap / Sector | D1: Investor Score | E1: Weight | F1: Capital (₹) | G1: Current Price (₹) | H1: Units | I1: Invested (₹) | J1: Beta | K1: Exp. Annual Return | L1: Target Price Oct-2029 (₹) | M1: Value Oct-2029 (₹)
A2: KEI | B2: Equity | C2: ='Master Fund Sheet'!B11&" / "&'Master Fund Sheet'!E11 -> Mid Cap / Electricals (Cables & Wires) | D2: ='Scoring Model'!AE32 -> 63.403846 | E2: 0.1 | F2: =E2*'Investor Personas'!$C$1 -> 1000000 | G2: =IFERROR(INDEX('Master Fund Sheet'!$I$2:$I$15,MATCH(A2,'Master Fund Sheet'!$C$2:$C$15,0)),0) -> 4648 | H2: =IF(G2>0,ROUNDDOWN(F2/G2,0),0) -> 215 | I2: =H2*G2 -> 999320 | J2: =IFERROR(INDEX('Risk Metrics'!$G$2:$G$15,MATCH(A2,'Risk Metrics'!$A$2:$A$15,0)),0) -> 1.4331655 | K2: =IFERROR(INDEX('Scoring Model'!$AQ$23:$AQ$36,MATCH(A2,'Scoring Model'!$A$23:$A$36,0)),0) -> 0.1632655 | L2: =G2*(1+K2)^'Investor Personas'!$F$1 -> 7316.4879 | M2: =I2*(1+K2)^'Investor Personas'!$F$1 -> 1573044.9
A3: EIHOTEL | B3: Equity | C3: ='Master Fund Sheet'!B15&" / "&'Master Fund Sheet'!E15 -> Small Cap / Hotels & Hospitality | D3: ='Scoring Model'!AE36 -> 52.615385 | E3: 0.09 | F3: =E3*'Investor Personas'!$C$1 -> 900000 | G3: =IFERROR(INDEX('Master Fund Sheet'!$I$2:$I$15,MATCH(A3,'Master Fund Sheet'!$C$2:$C$15,0)),0) -> 291.95 | H3: =IF(G3>0,ROUNDDOWN(F3/G3,0),0) -> 3082 | I3: =H3*G3 -> 899789.9 | J3: =IFERROR(INDEX('Risk Metrics'!$G$2:$G$15,MATCH(A3,'Risk Metrics'!$A$2:$A$15,0)),0) -> 1.1041444 | K3: =IFERROR(INDEX('Scoring Model'!$AQ$23:$AQ$36,MATCH(A3,'Scoring Model'!$A$23:$A$36,0)),0) -> 0.1418054 | L3: =G3*(1+K3)^'Investor Personas'!$F$1 -> 434.59503 | M3: =I3*(1+K3)^'Investor Personas'!$F$1 -> 1339421.9
A4: DABUR | B4: Equity | C4: ='Master Fund Sheet'!B9&" / "&'Master Fund Sheet'!E9 -> Mid Cap / Personal Care & Ayurveda | D4: ='Scoring Model'!AE30 -> 46.480769 | E4: 0.08 | F4: =E4*'Investor Personas'!$C$1 -> 800000 | G4: =IFERROR(INDEX('Master Fund Sheet'!$I$2:$I$15,MATCH(A4,'Master Fund Sheet'!$C$2:$C$15,0)),0) -> 388.4 | H4: =IF(G4>0,ROUNDDOWN(F4/G4,0),0) -> 2059 | I4: =H4*G4 -> 799715.6 | J4: =IFERROR(INDEX('Risk Metrics'!$G$2:$G$15,MATCH(A4,'Risk Metrics'!$A$2:$A$15,0)),0) -> 0.869804 | K4: =IFERROR(INDEX('Scoring Model'!$AQ$23:$AQ$36,MATCH(A4,'Scoring Model'!$A$23:$A$36,0)),0) -> 0.098594228 | L4: =G4*(1+K4)^'Investor Personas'!$F$1 -> 514.98095 | M4: =I4*(1+K4)^'Investor Personas'!$F$1 -> 1060345.8
A5: JUSTDIAL | B5: Equity | C5: ='Master Fund Sheet'!B14&" / "&'Master Fund Sheet'!E14 -> Small Cap / Internet / Local Search Services | D5: ='Scoring Model'!AE35 -> 46.230769 | E5: 0.08 | F5: =E5*'Investor Personas'!$C$1 -> 800000 | G5: =IFERROR(INDEX('Master Fund Sheet'!$I$2:$I$15,MATCH(A5,'Master Fund Sheet'!$C$2:$C$15,0)),0) -> 682.75 | H5: =IF(G5>0,ROUNDDOWN(F5/G5,0),0) -> 1171 | I5: =H5*G5 -> 799500.25 | J5: =IFERROR(INDEX('Risk Metrics'!$G$2:$G$15,MATCH(A5,'Risk Metrics'!$A$2:$A$15,0)),0) -> 1.2835508 | K5: =IFERROR(INDEX('Scoring Model'!$AQ$23:$AQ$36,MATCH(A5,'Scoring Model'!$A$23:$A$36,0)),0) -> 0.13013197 | L5: =G5*(1+K5)^'Investor Personas'!$F$1 -> 985.48313 | M5: =I5*(1+K5)^'Investor Personas'!$F$1 -> 1154000.7
A6: INFY | B6: Equity | C6: ='Master Fund Sheet'!B4&" / "&'Master Fund Sheet'!E4 -> Large Cap / IT Services | D6: ='Scoring Model'!AE25 -> 66.538462 | E6: 0.07 | F6: =E6*'Investor Personas'!$C$1 -> 700000 | G6: =IFERROR(INDEX('Master Fund Sheet'!$I$2:$I$15,MATCH(A6,'Master Fund Sheet'!$C$2:$C$15,0)),0) -> 1088 | H6: =IF(G6>0,ROUNDDOWN(F6/G6,0),0) -> 643 | I6: =H6*G6 -> 699584 | J6: =IFERROR(INDEX('Risk Metrics'!$G$2:$G$15,MATCH(A6,'Risk Metrics'!$A$2:$A$15,0)),0) -> 0.75751049 | K6: =IFERROR(INDEX('Scoring Model'!$AQ$23:$AQ$36,MATCH(A6,'Scoring Model'!$A$23:$A$36,0)),0) -> 0.15175839 | L6: =G6*(1+K6)^'Investor Personas'!$F$1 -> 1662.3139 | M6: =I6*(1+K6)^'Investor Personas'!$F$1 -> 1068867.9
A7: MARUTI | B7: Equity | C7: ='Master Fund Sheet'!B7&" / "&'Master Fund Sheet'!E7 -> Large Cap / Automobiles (Passenger Vehicles) | D7: ='Scoring Model'!AE28 -> 63.134615 | E7: 0.07 | F7: =E7*'Investor Personas'!$C$1 -> 700000 | G7: =IFERROR(INDEX('Master Fund Sheet'!$I$2:$I$15,MATCH(A7,'Master Fund Sheet'!$C$2:$C$15,0)),0) -> 11178 | H7: =IF(G7>0,ROUNDDOWN(F7/G7,0),0) -> 62 | I7: =H7*G7 -> 693036 | J7: =IFERROR(INDEX('Risk Metrics'!$G$2:$G$15,MATCH(A7,'Risk Metrics'!$A$2:$A$15,0)),0) -> 0.68561437 | K7: =IFERROR(INDEX('Scoring Model'!$AQ$23:$AQ$36,MATCH(A7,'Scoring Model'!$A$23:$A$36,0)),0) -> 0.12544508 | L7: =G7*(1+K7)^'Investor Personas'!$F$1 -> 15934.448 | M7: =I7*(1+K7)^'Investor Personas'!$F$1 -> 987935.79
A8: ASTRAL | B8: Equity | C8: ='Master Fund Sheet'!B10&" / "&'Master Fund Sheet'!E10 -> Mid Cap / Building Materials (Pipes) | D8: ='Scoring Model'!AE31 -> 45.115385 | E8: 0.07 | F8: =E8*'Investor Personas'!$C$1 -> 700000 | G8: =IFERROR(INDEX('Master Fund Sheet'!$I$2:$I$15,MATCH(A8,'Master Fund Sheet'!$C$2:$C$15,0)),0) -> 1443.2 | H8: =IF(G8>0,ROUNDDOWN(F8/G8,0),0) -> 485 | I8: =H8*G8 -> 699952 | J8: =IFERROR(INDEX('Risk Metrics'!$G$2:$G$15,MATCH(A8,'Risk Metrics'!$A$2:$A$15,0)),0) -> 0.69741418 | K8: =IFERROR(INDEX('Scoring Model'!$AQ$23:$AQ$36,MATCH(A8,'Scoring Model'!$A$23:$A$36,0)),0) -> 0.1148254 | L8: =G8*(1+K8)^'Investor Personas'!$F$1 -> 1999.6182 | M8: =I8*(1+K8)^'Investor Personas'!$F$1 -> 969814.83
A9: RELIANCE | B9: Equity | C9: ='Master Fund Sheet'!B2&" / "&'Master Fund Sheet'!E2 -> Large Cap / Oil & Gas / Conglomerate | D9: ='Scoring Model'!AE23 -> 53.307692 | E9: 0.06 | F9: =E9*'Investor Personas'!$C$1 -> 600000 | G9: =IFERROR(INDEX('Master Fund Sheet'!$I$2:$I$15,MATCH(A9,'Master Fund Sheet'!$C$2:$C$15,0)),0) -> 1174.6 | H9: =IF(G9>0,ROUNDDOWN(F9/G9,0),0) -> 510 | I9: =H9*G9 -> 599046 | J9: =IFERROR(INDEX('Risk Metrics'!$G$2:$G$15,MATCH(A9,'Risk Metrics'!$A$2:$A$15,0)),0) -> 0.99084157 | K9: =IFERROR(INDEX('Scoring Model'!$AQ$23:$AQ$36,MATCH(A9,'Scoring Model'!$A$23:$A$36,0)),0) -> 0.11637344 | L9: =G9*(1+K9)^'Investor Personas'!$F$1 -> 1634.2499 | M9: =I9*(1+K9)^'Investor Personas'!$F$1 -> 833467.47
A10: HDFCBANK | B10: Equity | C10: ='Master Fund Sheet'!B3&" / "&'Master Fund Sheet'!E3 -> Large Cap / Private Sector Banking | D10: ='Scoring Model'!AE24 -> 57.019231 | E10: 0.06 | F10: =E10*'Investor Personas'!$C$1 -> 600000 | G10: =IFERROR(INDEX('Master Fund Sheet'!$I$2:$I$15,MATCH(A10,'Master Fund Sheet'!$C$2:$C$15,0)),0) -> 710.7 | H10: =IF(G10>0,ROUNDDOWN(F10/G10,0),0) -> 844 | I10: =H10*G10 -> 599830.8 | J10: =IFERROR(INDEX('Risk Metrics'!$G$2:$G$15,MATCH(A10,'Risk Metrics'!$A$2:$A$15,0)),0) -> 0.884506 | K10: =IFERROR(INDEX('Scoring Model'!$AQ$23:$AQ$36,MATCH(A10,'Scoring Model'!$A$23:$A$36,0)),0) -> 0.13305021 | L10: =G10*(1+K10)^'Investor Personas'!$F$1 -> 1033.7935 | M10: =I10*(1+K10)^'Investor Personas'!$F$1 -> 872521.69
A11: SUNPHARMA | B11: Equity | C11: ='Master Fund Sheet'!B6&" / "&'Master Fund Sheet'!E6 -> Large Cap / Pharmaceuticals | D11: ='Scoring Model'!AE27 -> 60.75 | E11: 0.06 | F11: =E11*'Investor Personas'!$C$1 -> 600000 | G11: =IFERROR(INDEX('Master Fund Sheet'!$I$2:$I$15,MATCH(A11,'Master Fund Sheet'!$C$2:$C$15,0)),0) -> 1746.4 | H11: =IF(G11>0,ROUNDDOWN(F11/G11,0),0) -> 343 | I11: =H11*G11 -> 599015.2 | J11: =IFERROR(INDEX('Risk Metrics'!$G$2:$G$15,MATCH(A11,'Risk Metrics'!$A$2:$A$15,0)),0) -> 0.87112781 | K11: =IFERROR(INDEX('Scoring Model'!$AQ$23:$AQ$36,MATCH(A11,'Scoring Model'!$A$23:$A$36,0)),0) -> 0.13254155 | L11: =G11*(1+K11)^'Investor Personas'!$F$1 -> 2536.9164 | M11: =I11*(1+K11)^'Investor Personas'!$F$1 -> 870162.32
A12: TATASTEEL | B12: Equity | C12: ='Master Fund Sheet'!B8&" / "&'Master Fund Sheet'!E8 -> Large Cap / Metals & Mining (Steel) | D12: ='Scoring Model'!AE29 -> 52.576923 | E12: 0.06 | F12: =E12*'Investor Personas'!$C$1 -> 600000 | G12: =IFERROR(INDEX('Master Fund Sheet'!$I$2:$I$15,MATCH(A12,'Master Fund Sheet'!$C$2:$C$15,0)),0) -> 174.49 | H12: =IF(G12>0,ROUNDDOWN(F12/G12,0),0) -> 3438 | I12: =H12*G12 -> 599896.62 | J12: =IFERROR(INDEX('Risk Metrics'!$G$2:$G$15,MATCH(A12,'Risk Metrics'!$A$2:$A$15,0)),0) -> 1.1923044 | K12: =IFERROR(INDEX('Scoring Model'!$AQ$23:$AQ$36,MATCH(A12,'Scoring Model'!$A$23:$A$36,0)),0) -> 0.12246547 | L12: =G12*(1+K12)^'Investor Personas'!$F$1 -> 246.76838 | M12: =I12*(1+K12)^'Investor Personas'!$F$1 -> 848389.69
A13: ITC | B13: Equity | C13: ='Master Fund Sheet'!B5&" / "&'Master Fund Sheet'!E5 -> Large Cap / FMCG (Cigarettes, Foods, Agri) | D13: ='Scoring Model'!AE26 -> 47.211538 | E13: 0.05 | F13: =E13*'Investor Personas'!$C$1 -> 500000 | G13: =IFERROR(INDEX('Master Fund Sheet'!$I$2:$I$15,MATCH(A13,'Master Fund Sheet'!$C$2:$C$15,0)),0) -> 261.5 | H13: =IF(G13>0,ROUNDDOWN(F13/G13,0),0) -> 1912 | I13: =H13*G13 -> 499988 | J13: =IFERROR(INDEX('Risk Metrics'!$G$2:$G$15,MATCH(A13,'Risk Metrics'!$A$2:$A$15,0)),0) -> 0.81842432 | K13: =IFERROR(INDEX('Scoring Model'!$AQ$23:$AQ$36,MATCH(A13,'Scoring Model'!$A$23:$A$36,0)),0) -> 0.10578484 | L13: =G13*(1+K13)^'Investor Personas'!$F$1 -> 353.57666 | M13: =I13*(1+K13)^'Investor Personas'!$F$1 -> 676038.58
A14: GSEC-3Y | B14: Bonds | C14: ='Master Fund Sheet'!G18&" / "&'Master Fund Sheet'!B18 -> Sovereign (SOV) / Government Bond | D14: — | E14: 0.05 | F14: =E14*'Investor Personas'!$C$1 -> 500000 | G14: ='Master Fund Sheet'!H18 -> 100 | H14: =IF(G14>0,ROUNDDOWN(F14/G14,0),0) -> 5000 | I14: =H14*G14 -> 500000 | J14: 0 | K14: ='Master Fund Sheet'!M18 -> 0.0707 | L14: =G14*(1+K14)^'Investor Personas'!$F$1 -> 122.74489 | M14: =I14*(1+K14)^'Investor Personas'!$F$1 -> 613724.43
A15: RIL-NCD-2036 | B15: Bonds | C15: ='Master Fund Sheet'!G19&" / "&'Master Fund Sheet'!B19 -> CRISIL AAA / CARE AAA / Corporate Bond | D15: — | E15: 0.05 | F15: =E15*'Investor Personas'!$C$1 -> 500000 | G15: ='Master Fund Sheet'!H19 -> 100000 | H15: =IF(G15>0,ROUNDDOWN(F15/G15,0),0) -> 5 | I15: =H15*G15 -> 500000 | J15: 0 | K15: ='Master Fund Sheet'!M19 -> 0.07875 | L15: =G15*(1+K15)^'Investor Personas'!$F$1 -> 125534.31 | M15: =I15*(1+K15)^'Investor Personas'!$F$1 -> 627671.53
A16: SMC-NCD-2029 | B16: Bonds | C16: ='Master Fund Sheet'!G20&" / "&'Master Fund Sheet'!B20 -> ICRA A (Stable) / Corporate Bond | D16: — | E16: 0.05 | F16: =E16*'Investor Personas'!$C$1 -> 500000 | G16: ='Master Fund Sheet'!H20 -> 1000 | H16: =IF(G16>0,ROUNDDOWN(F16/G16,0),0) -> 500 | I16: =H16*G16 -> 500000 | J16: 0 | K16: ='Master Fund Sheet'!M20 -> 0.0945 | L16: =G16*(1+K16)^'Investor Personas'!$F$1 -> 1311.1347 | M16: =I16*(1+K16)^'Investor Personas'!$F$1 -> 655567.33
A18: TOTAL | E18: =SUM(E2:E16) -> 1 | F18: =SUM(F2:F16) -> 10000000 | H18: =COUNTIF(B2:B16,"Equity")&" stocks" -> 12 stocks | I18: =SUM(I2:I16) -> 9988674.4 | M18: =SUM(M2:M16) -> 14150975
A20: PORTFOLIO SUMMARY
A21: Corpus | B21: ='Investor Personas'!$C$1 -> 10000000 | D21: The Growth Architect · 38, strategy consultant, dual income. Targets the lower assignment target with some debt ballast.
A22: Invested | B22: =I18 -> 9988674.4 | D22: Policy: 85% equity split 50/30/20 Large/Mid/Small; stocks need investor score ≥ 40 and beta ≤ 1.7; weight ∝ score within each segment, rounded to whole %.
A23: Uninvested cash (earns 3Y G-Sec yield) | B23: =B21-B22 -> 11325.63 | D23: Not selected: BATAINDIA, ZEEL
A24: Weighted portfolio beta | B24: =SUMPRODUCT(I2:I16,J2:J16)/B21 -> 0.84111323
A25: Projected value Oct-2029 | B25: =M18+B23*(1+'Master Fund Sheet'!$I$18)^'Investor Personas'!$F$1 -> 14164876
A26: Expected CAGR | B26: =(B25/B21)^(1/'Investor Personas'!$F$1)-1 -> 0.12306337
A27: Target | B27: ='Investor Personas'!C4 -> 20000000
A28: CAGR required | B28: ='Investor Personas'!D4 -> 0.25992105
A29: Surplus / (shortfall) | B29: =B25-B27 -> -5835123.6
A30: Portfolio SD (5Y history) | B30: ='Risk Metrics'!C91 -> 0.13370298
A31: Probability of reaching target | B31: =1-NORMSDIST((LN(B27/B21)-LN(1+B26)*'Investor Personas'!$F$1)/(B30*SQRT('Investor Personas'!$F$1))) -> 0.068162017

Sheet Rohan
A1: Asset / Ticker | B1: Asset Class | C1: Cap / Sector | D1: Investor Score | E1: Weight | F1: Capital (₹) | G1: Current Price (₹) | H1: Units | I1: Invested (₹) | J1: Beta | K1: Exp. Annual Return | L1: Target Price Oct-2029 (₹) | M1: Value Oct-2029 (₹)
A2: INFY | B2: Equity | C2: ='Master Fund Sheet'!B4&" / "&'Master Fund Sheet'!E4 -> Large Cap / IT Services | D2: ='Scoring Model'!AF25 -> 67.717949 | E2: 0.07 | F2: =E2*'Investor Personas'!$C$1 -> 700000 | G2: =IFERROR(INDEX('Master Fund Sheet'!$I$2:$I$15,MATCH(A2,'Master Fund Sheet'!$C$2:$C$15,0)),0) -> 1088 | H2: =IF(G2>0,ROUNDDOWN(F2/G2,0),0) -> 643 | I2: =H2*G2 -> 699584 | J2: =IFERROR(INDEX('Risk Metrics'!$G$2:$G$15,MATCH(A2,'Risk Metrics'!$A$2:$A$15,0)),0) -> 0.75751049 | K2: =IFERROR(INDEX('Scoring Model'!$AQ$23:$AQ$36,MATCH(A2,'Scoring Model'!$A$23:$A$36,0)),0) -> 0.15175839 | L2: =G2*(1+K2)^'Investor Personas'!$F$1 -> 1662.3139 | M2: =I2*(1+K2)^'Investor Personas'!$F$1 -> 1068867.9
A3: MARUTI | B3: Equity | C3: ='Master Fund Sheet'!B7&" / "&'Master Fund Sheet'!E7 -> Large Cap / Automobiles (Passenger Vehicles) | D3: ='Scoring Model'!AF28 -> 65.865385 | E3: 0.07 | F3: =E3*'Investor Personas'!$C$1 -> 700000 | G3: =IFERROR(INDEX('Master Fund Sheet'!$I$2:$I$15,MATCH(A3,'Master Fund Sheet'!$C$2:$C$15,0)),0) -> 11178 | H3: =IF(G3>0,ROUNDDOWN(F3/G3,0),0) -> 62 | I3: =H3*G3 -> 693036 | J3: =IFERROR(INDEX('Risk Metrics'!$G$2:$G$15,MATCH(A3,'Risk Metrics'!$A$2:$A$15,0)),0) -> 0.68561437 | K3: =IFERROR(INDEX('Scoring Model'!$AQ$23:$AQ$36,MATCH(A3,'Scoring Model'!$A$23:$A$36,0)),0) -> 0.12544508 | L3: =G3*(1+K3)^'Investor Personas'!$F$1 -> 15934.448 | M3: =I3*(1+K3)^'Investor Personas'!$F$1 -> 987935.79
A4: RELIANCE | B4: Equity | C4: ='Master Fund Sheet'!B2&" / "&'Master Fund Sheet'!E2 -> Large Cap / Oil & Gas / Conglomerate | D4: ='Scoring Model'!AF23 -> 56.205128 | E4: 0.06 | F4: =E4*'Investor Personas'!$C$1 -> 600000 | G4: =IFERROR(INDEX('Master Fund Sheet'!$I$2:$I$15,MATCH(A4,'Master Fund Sheet'!$C$2:$C$15,0)),0) -> 1174.6 | H4: =IF(G4>0,ROUNDDOWN(F4/G4,0),0) -> 510 | I4: =H4*G4 -> 599046 | J4: =IFERROR(INDEX('Risk Metrics'!$G$2:$G$15,MATCH(A4,'Risk Metrics'!$A$2:$A$15,0)),0) -> 0.99084157 | K4: =IFERROR(INDEX('Scoring Model'!$AQ$23:$AQ$36,MATCH(A4,'Scoring Model'!$A$23:$A$36,0)),0) -> 0.11637344 | L4: =G4*(1+K4)^'Investor Personas'!$F$1 -> 1634.2499 | M4: =I4*(1+K4)^'Investor Personas'!$F$1 -> 833467.47
A5: HDFCBANK | B5: Equity | C5: ='Master Fund Sheet'!B3&" / "&'Master Fund Sheet'!E3 -> Large Cap / Private Sector Banking | D5: ='Scoring Model'!AF24 -> 59.49359 | E5: 0.06 | F5: =E5*'Investor Personas'!$C$1 -> 600000 | G5: =IFERROR(INDEX('Master Fund Sheet'!$I$2:$I$15,MATCH(A5,'Master Fund Sheet'!$C$2:$C$15,0)),0) -> 710.7 | H5: =IF(G5>0,ROUNDDOWN(F5/G5,0),0) -> 844 | I5: =H5*G5 -> 599830.8 | J5: =IFERROR(INDEX('Risk Metrics'!$G$2:$G$15,MATCH(A5,'Risk Metrics'!$A$2:$A$15,0)),0) -> 0.884506 | K5: =IFERROR(INDEX('Scoring Model'!$AQ$23:$AQ$36,MATCH(A5,'Scoring Model'!$A$23:$A$36,0)),0) -> 0.13305021 | L5: =G5*(1+K5)^'Investor Personas'!$F$1 -> 1033.7935 | M5: =I5*(1+K5)^'Investor Personas'!$F$1 -> 872521.69
A6: SUNPHARMA | B6: Equity | C6: ='Master Fund Sheet'!B6&" / "&'Master Fund Sheet'!E6 -> Large Cap / Pharmaceuticals | D6: ='Scoring Model'!AF27 -> 60.455128 | E6: 0.06 | F6: =E6*'Investor Personas'!$C$1 -> 600000 | G6: =IFERROR(INDEX('Master Fund Sheet'!$I$2:$I$15,MATCH(A6,'Master Fund Sheet'!$C$2:$C$15,0)),0) -> 1746.4 | H6: =IF(G6>0,ROUNDDOWN(F6/G6,0),0) -> 343 | I6: =H6*G6 -> 599015.2 | J6: =IFERROR(INDEX('Risk Metrics'!$G$2:$G$15,MATCH(A6,'Risk Metrics'!$A$2:$A$15,0)),0) -> 0.87112781 | K6: =IFERROR(INDEX('Scoring Model'!$AQ$23:$AQ$36,MATCH(A6,'Scoring Model'!$A$23:$A$36,0)),0) -> 0.13254155 | L6: =G6*(1+K6)^'Investor Personas'!$F$1 -> 2536.9164 | M6: =I6*(1+K6)^'Investor Personas'!$F$1 -> 870162.32
A7: KEI | B7: Equity | C7: ='Master Fund Sheet'!B11&" / "&'Master Fund Sheet'!E11 -> Mid Cap / Electricals (Cables & Wires) | D7: ='Scoring Model'!AF32 -> 57.801282 | E7: 0.06 | F7: =E7*'Investor Personas'!$C$1 -> 600000 | G7: =IFERROR(INDEX('Master Fund Sheet'!$I$2:$I$15,MATCH(A7,'Master Fund Sheet'!$C$2:$C$15,0)),0) -> 4648 | H7: =IF(G7>0,ROUNDDOWN(F7/G7,0),0) -> 129 | I7: =H7*G7 -> 599592 | J7: =IFERROR(INDEX('Risk Metrics'!$G$2:$G$15,MATCH(A7,'Risk Metrics'!$A$2:$A$15,0)),0) -> 1.4331655 | K7: =IFERROR(INDEX('Scoring Model'!$AQ$23:$AQ$36,MATCH(A7,'Scoring Model'!$A$23:$A$36,0)),0) -> 0.1632655 | L7: =G7*(1+K7)^'Investor Personas'!$F$1 -> 7316.4879 | M7: =I7*(1+K7)^'Investor Personas'!$F$1 -> 943826.94
A8: ITC | B8: Equity | C8: ='Master Fund Sheet'!B5&" / "&'Master Fund Sheet'!E5 -> Large Cap / FMCG (Cigarettes, Foods, Agri) | D8: ='Scoring Model'!AF26 -> 51.903846 | E8: 0.05 | F8: =E8*'Investor Personas'!$C$1 -> 500000 | G8: =IFERROR(INDEX('Master Fund Sheet'!$I$2:$I$15,MATCH(A8,'Master Fund Sheet'!$C$2:$C$15,0)),0) -> 261.5 | H8: =IF(G8>0,ROUNDDOWN(F8/G8,0),0) -> 1912 | I8: =H8*G8 -> 499988 | J8: =IFERROR(INDEX('Risk Metrics'!$G$2:$G$15,MATCH(A8,'Risk Metrics'!$A$2:$A$15,0)),0) -> 0.81842432 | K8: =IFERROR(INDEX('Scoring Model'!$AQ$23:$AQ$36,MATCH(A8,'Scoring Model'!$A$23:$A$36,0)),0) -> 0.10578484 | L8: =G8*(1+K8)^'Investor Personas'!$F$1 -> 353.57666 | M8: =I8*(1+K8)^'Investor Personas'!$F$1 -> 676038.58
A9: TATASTEEL | B9: Equity | C9: ='Master Fund Sheet'!B8&" / "&'Master Fund Sheet'!E8 -> Large Cap / Metals & Mining (Steel) | D9: ='Scoring Model'!AF29 -> 50.576923 | E9: 0.05 | F9: =E9*'Investor Personas'!$C$1 -> 500000 | G9: =IFERROR(INDEX('Master Fund Sheet'!$I$2:$I$15,MATCH(A9,'Master Fund Sheet'!$C$2:$C$15,0)),0) -> 174.49 | H9: =IF(G9>0,ROUNDDOWN(F9/G9,0),0) -> 2865 | I9: =H9*G9 -> 499913.85 | J9: =IFERROR(INDEX('Risk Metrics'!$G$2:$G$15,MATCH(A9,'Risk Metrics'!$A$2:$A$15,0)),0) -> 1.1923044 | K9: =IFERROR(INDEX('Scoring Model'!$AQ$23:$AQ$36,MATCH(A9,'Scoring Model'!$A$23:$A$36,0)),0) -> 0.12246547 | L9: =G9*(1+K9)^'Investor Personas'!$F$1 -> 246.76838 | M9: =I9*(1+K9)^'Investor Personas'!$F$1 -> 706991.41
A10: DABUR | B10: Equity | C10: ='Master Fund Sheet'!B9&" / "&'Master Fund Sheet'!E9 -> Mid Cap / Personal Care & Ayurveda | D10: ='Scoring Model'!AF30 -> 47.429487 | E10: 0.05 | F10: =E10*'Investor Personas'!$C$1 -> 500000 | G10: =IFERROR(INDEX('Master Fund Sheet'!$I$2:$I$15,MATCH(A10,'Master Fund Sheet'!$C$2:$C$15,0)),0) -> 388.4 | H10: =IF(G10>0,ROUNDDOWN(F10/G10,0),0) -> 1287 | I10: =H10*G10 -> 499870.8 | J10: =IFERROR(INDEX('Risk Metrics'!$G$2:$G$15,MATCH(A10,'Risk Metrics'!$A$2:$A$15,0)),0) -> 0.869804 | K10: =IFERROR(INDEX('Scoring Model'!$AQ$23:$AQ$36,MATCH(A10,'Scoring Model'!$A$23:$A$36,0)),0) -> 0.098594228 | L10: =G10*(1+K10)^'Investor Personas'!$F$1 -> 514.98095 | M10: =I10*(1+K10)^'Investor Personas'!$F$1 -> 662780.48
A11: ASTRAL | B11: Equity | C11: ='Master Fund Sheet'!B10&" / "&'Master Fund Sheet'!E10 -> Mid Cap / Building Materials (Pipes) | D11: ='Scoring Model'!AF31 -> 44.410256 | E11: 0.05 | F11: =E11*'Investor Personas'!$C$1 -> 500000 | G11: =IFERROR(INDEX('Master Fund Sheet'!$I$2:$I$15,MATCH(A11,'Master Fund Sheet'!$C$2:$C$15,0)),0) -> 1443.2 | H11: =IF(G11>0,ROUNDDOWN(F11/G11,0),0) -> 346 | I11: =H11*G11 -> 499347.2 | J11: =IFERROR(INDEX('Risk Metrics'!$G$2:$G$15,MATCH(A11,'Risk Metrics'!$A$2:$A$15,0)),0) -> 0.69741418 | K11: =IFERROR(INDEX('Scoring Model'!$AQ$23:$AQ$36,MATCH(A11,'Scoring Model'!$A$23:$A$36,0)),0) -> 0.1148254 | L11: =G11*(1+K11)^'Investor Personas'!$F$1 -> 1999.6182 | M11: =I11*(1+K11)^'Investor Personas'!$F$1 -> 691867.9
